2024-09-07 18:23:51.954 | ERROR    | app.core.logger:log_exception:88 - Обработана ошибка: name 'logger' is not defined
2024-09-07 18:23:53.239 | ERROR    | app.core.logger:log_exception:88 - Обработана ошибка: name 'logger' is not defined
2024-09-07 18:24:43.934 | ERROR    | app.core.logger:log_exception:88 - Обработана ошибка: name 'logger' is not defined
2024-09-07 18:24:44.149 | ERROR    | app.core.logger:log_exception:88 - Обработана ошибка: name 'logger' is not defined
2024-09-07 18:26:17.349 | INFO     | app.main:log_requests:44 - GET http://127.0.0.1:8000/docs - 200
2024-09-07 18:26:18.129 | INFO     | app.main:log_requests:44 - GET http://127.0.0.1:8000/openapi.json - 200
2024-09-07 18:27:07.737 | ERROR    | app.core.logger:log_exception:88 - Обработана ошибка: name 'telegram_service' is not defined
2024-09-07 18:28:19.309 | ERROR    | app.core.logger:log_exception:88 - Обработана ошибка: 'NoneType' object has no attribute 'token'
2024-09-07 18:32:22.487 | ERROR    | app.core.logger:log_exception:88 - Обработана ошибка: Client.get() got an unexpected keyword argument 'json'
2024-09-07 18:33:12.348 | ERROR    | app.core.logger:log_exception:88 - Обработана ошибка: 2 validation errors for UserSchema
created_at
  Field required [type=missing, input_value={'id': UUID('a30df21f-d61...il': 'user@example.com'}, input_type=dict]
    For further information visit https://errors.pydantic.dev/2.8/v/missing
updated_at
  Field required [type=missing, input_value={'id': UUID('a30df21f-d61...il': 'user@example.com'}, input_type=dict]
    For further information visit https://errors.pydantic.dev/2.8/v/missing
2024-09-07 18:35:13.447 | INFO     | app.main:log_requests:44 - POST http://127.0.0.1:8000/api/v1/users/ - 400
2024-09-07 18:37:54.928 | ERROR    | app.core.logger:log_exception:88 - Обработана ошибка: 2 validation errors for UserSchema
created_at
  Input should be a valid string [type=string_type, input_value=datetime.datetime(2024, 9, 7, 15, 37, 54), input_type=datetime]
    For further information visit https://errors.pydantic.dev/2.8/v/string_type
updated_at
  Input should be a valid string [type=string_type, input_value=datetime.datetime(2024, 9, 7, 15, 37, 54), input_type=datetime]
    For further information visit https://errors.pydantic.dev/2.8/v/string_type
2024-09-07 18:39:33.168 | INFO     | app.main:log_requests:44 - POST http://127.0.0.1:8000/api/v1/users/ - 201
2024-09-07 18:40:03.973 | INFO     | app.main:log_requests:44 - POST http://127.0.0.1:8000/api/v1/users/ - 400
2024-09-07 18:42:27.812 | INFO     | app.main:log_requests:44 - POST http://127.0.0.1:8000/api/v1/users/ - 400
2024-09-07 18:42:40.029 | INFO     | app.main:log_requests:44 - POST http://127.0.0.1:8000/api/v1/auth/login - 200
2024-09-07 18:42:52.453 | INFO     | app.main:log_requests:44 - GET http://127.0.0.1:8000/api/v1/users/me - 403
2024-09-07 18:43:00.596 | ERROR    | app.core.logger:log_exception:88 - Обработана ошибка: 'Provide' object has no attribute 'decode'
2024-09-07 18:47:38.845 | ERROR    | app.core.logger:log_exception:88 - Обработана ошибка: 2 validation errors for UserSchema
created_at
  Field required [type=missing, input_value={'id': UUID('e50126b9-80a...il': 'user@example.com'}, input_type=dict]
    For further information visit https://errors.pydantic.dev/2.8/v/missing
updated_at
  Field required [type=missing, input_value={'id': UUID('e50126b9-80a...il': 'user@example.com'}, input_type=dict]
    For further information visit https://errors.pydantic.dev/2.8/v/missing
2024-09-07 18:49:01.412 | ERROR    | app.core.logger:log_exception:88 - Обработана ошибка: 2 validation errors for UserSchema
created_at
  Input should be a valid string [type=string_type, input_value=datetime.datetime(2024, 9, 7, 15, 39, 32), input_type=datetime]
    For further information visit https://errors.pydantic.dev/2.8/v/string_type
updated_at
  Input should be a valid string [type=string_type, input_value=datetime.datetime(2024, 9, 7, 15, 39, 32), input_type=datetime]
    For further information visit https://errors.pydantic.dev/2.8/v/string_type
2024-09-07 18:50:30.094 | INFO     | app.main:log_requests:44 - GET http://127.0.0.1:8000/api/v1/users/me - 200
2024-09-07 18:50:59.793 | INFO     | app.main:log_requests:44 - POST http://127.0.0.1:8000/api/v1/auth/login - 200
2024-09-07 18:51:29.189 | INFO     | app.main:log_requests:44 - POST http://127.0.0.1:8000/api/v1/auth/refresh - 200
2024-09-07 18:51:41.843 | INFO     | app.main:log_requests:44 - POST http://127.0.0.1:8000/api/v1/auth/logout - 200
2024-09-07 18:51:50.003 | INFO     | app.main:log_requests:44 - GET http://127.0.0.1:8000/api/v1/users/me - 200
2024-09-07 18:34:45.568 | INFO     | app.main:log_requests:44 - GET http://127.0.0.1:8000/docs - 200
2024-09-07 18:34:46.383 | INFO     | app.main:log_requests:44 - GET http://127.0.0.1:8000/openapi.json - 200
2024-09-07 18:35:45.981 | INFO     | app.main:log_requests:44 - GET http://127.0.0.1:8000/docs - 200
2024-09-07 18:35:46.550 | INFO     | app.main:log_requests:44 - GET http://127.0.0.1:8000/openapi.json - 200
2024-09-07 18:35:52.257 | INFO     | app.main:log_requests:44 - POST http://127.0.0.1:8000/api/v1/notes/ - 403
2024-09-07 18:35:58.559 | INFO     | app.main:log_requests:44 - GET http://127.0.0.1:8000/api/v1/notes/?limit=10&skip=0 - 403
2024-09-07 18:36:10.867 | INFO     | app.main:log_requests:44 - POST http://127.0.0.1:8000/api/v1/auth/login - 200
2024-09-07 18:37:05.773 | ERROR    | app.core.logger:log_exception:88 - Обработана ошибка: RepositoryNote.__init__() got an unexpected keyword argument 'model'
2024-09-07 18:39:00.270 | ERROR    | app.core.logger:log_exception:88 - Обработана ошибка: NoteService.create_note() got an unexpected keyword argument 'obj_in'
2024-09-07 18:39:53.009 | ERROR    | app.core.logger:log_exception:88 - Обработана ошибка: NoteService.create_note() got multiple values for argument 'obj_in'
2024-09-07 18:40:37.439 | ERROR    | app.core.logger:log_exception:88 - Обработана ошибка: NoteService.create_note() got multiple values for argument 'obj_in'
2024-09-07 18:42:11.866 | ERROR    | app.core.logger:log_exception:88 - Обработана ошибка: NoteService.create_note() got multiple values for argument 'obj_in'
2024-09-07 18:43:28.585 | ERROR    | app.core.logger:log_exception:88 - Обработана ошибка: NoteService.create_note() got multiple values for argument 'obj_in'
2024-09-07 18:44:33.901 | ERROR    | app.core.logger:log_exception:88 - Обработана ошибка: name 'create_note_tags_schema' is not defined
2024-09-07 18:45:09.231 | ERROR    | app.core.logger:log_exception:88 - Обработана ошибка: RepositoryTag.bulk_create() got multiple values for argument 'tags_names'
2024-09-07 18:45:51.997 | ERROR    | app.core.logger:log_exception:88 - Обработана ошибка: 'coroutine' object has no attribute 'tags'
2024-09-07 18:48:28.392 | ERROR    | app.core.logger:log_exception:88 - Обработана ошибка: 'user_id' is an invalid keyword argument for Note
2024-09-07 18:50:36.020 | INFO     | app.main:log_requests:44 - POST http://127.0.0.1:8000/api/v1/notes/ - 422
2024-09-07 18:50:56.859 | ERROR    | app.core.logger:log_exception:88 - Обработана ошибка: 'tags_names' is an invalid keyword argument for Note
2024-09-07 18:52:22.956 | ERROR    | app.core.logger:log_exception:88 - Обработана ошибка: Incompatible collection type: coroutine is not list-like
2024-09-07 18:55:20.953 | ERROR    | app.core.logger:log_exception:88 - Обработана ошибка: Incompatible collection type: coroutine is not list-like
2024-09-07 18:56:35.488 | INFO     | app.main:log_requests:44 - POST http://127.0.0.1:8000/api/v1/notes/ - 401
2024-09-07 18:56:49.087 | INFO     | app.main:log_requests:44 - POST http://127.0.0.1:8000/api/v1/auth/login - 200
2024-09-07 17:57:01.643 | INFO     | app.main:log_requests:44 - POST http://127.0.0.1:8000/api/v1/notes/ - 401
2024-09-07 17:57:28.621 | INFO     | app.main:log_requests:44 - POST http://127.0.0.1:8000/api/v1/auth/login - 200
2024-09-07 17:57:44.768 | ERROR    | app.core.logger:log_exception:88 - Обработана ошибка: name 'tags_data' is not defined
2024-09-07 17:58:36.811 | ERROR    | app.core.logger:log_exception:88 - Обработана ошибка: 'AsyncSession' object has no attribute 'query'
2024-09-07 18:00:24.784 | ERROR    | app.core.logger:log_exception:88 - Обработана ошибка: name 'tag_names' is not defined
2024-09-07 18:00:47.762 | ERROR    | app.core.logger:log_exception:88 - Обработана ошибка: (sqlite3.IntegrityError) NOT NULL constraint failed: tags.name
[SQL: INSERT INTO tags (id) VALUES (?) RETURNING name, id]
[parameters: ('7a3baec69adb4b0ab6f16920afc98875',)]
(Background on this error at: https://sqlalche.me/e/20/gkpj)
2024-09-07 18:01:33.357 | ERROR    | app.core.logger:log_exception:88 - Обработана ошибка: (sqlite3.IntegrityError) NOT NULL constraint failed: tags.name
[SQL: INSERT INTO tags (id) VALUES (?) RETURNING name, id]
[parameters: ('ded84dbbd0104ec98faaf118d33fae4a',)]
(Background on this error at: https://sqlalche.me/e/20/gkpj)
2024-09-07 18:02:29.239 | INFO     | app.main:log_requests:44 - GET http://127.0.0.1:8000/docs - 200
2024-09-07 18:02:30.624 | INFO     | app.main:log_requests:44 - GET http://127.0.0.1:8000/openapi.json - 200
2024-09-07 18:02:38.933 | INFO     | app.main:log_requests:44 - POST http://127.0.0.1:8000/api/v1/auth/login - 200
2024-09-07 18:03:29.973 | ERROR    | app.core.logger:log_exception:88 - Обработана ошибка: 'str' object has no attribute 'name'
2024-09-07 18:04:02.608 | ERROR    | app.core.logger:log_exception:88 - Обработана ошибка: greenlet_spawn has not been called; can't call await_only() here. Was IO attempted in an unexpected place? (Background on this error at: https://sqlalche.me/e/20/xd2s)
2024-09-07 18:05:57.139 | ERROR    | app.core.logger:log_exception:88 - Обработана ошибка: 5 validation errors:
  {'type': 'missing', 'loc': ('response', 'title'), 'msg': 'Field required', 'input': {'e': "(sqlite3.IntegrityError) UNIQUE constraint failed: tags.name\n[SQL: INSERT INTO tags (name, id) VALUES (?, ?), (?, ?) RETURNING name, id]\n[parameters: ('Гигиена', 'c42b94f4d0aa4910bc9241508540d8f8', 'Ванна', '1e773a3fbf3c41f7a815a48b301d0283')]\n(Background on this error at: https://sqlalche.me/e/20/gkpj)"}}
  {'type': 'missing', 'loc': ('response', 'content'), 'msg': 'Field required', 'input': {'e': "(sqlite3.IntegrityError) UNIQUE constraint failed: tags.name\n[SQL: INSERT INTO tags (name, id) VALUES (?, ?), (?, ?) RETURNING name, id]\n[parameters: ('Гигиена', 'c42b94f4d0aa4910bc9241508540d8f8', 'Ванна', '1e773a3fbf3c41f7a815a48b301d0283')]\n(Background on this error at: https://sqlalche.me/e/20/gkpj)"}}
  {'type': 'missing', 'loc': ('response', 'id'), 'msg': 'Field required', 'input': {'e': "(sqlite3.IntegrityError) UNIQUE constraint failed: tags.name\n[SQL: INSERT INTO tags (name, id) VALUES (?, ?), (?, ?) RETURNING name, id]\n[parameters: ('Гигиена', 'c42b94f4d0aa4910bc9241508540d8f8', 'Ванна', '1e773a3fbf3c41f7a815a48b301d0283')]\n(Background on this error at: https://sqlalche.me/e/20/gkpj)"}}
  {'type': 'missing', 'loc': ('response', 'created_at'), 'msg': 'Field required', 'input': {'e': "(sqlite3.IntegrityError) UNIQUE constraint failed: tags.name\n[SQL: INSERT INTO tags (name, id) VALUES (?, ?), (?, ?) RETURNING name, id]\n[parameters: ('Гигиена', 'c42b94f4d0aa4910bc9241508540d8f8', 'Ванна', '1e773a3fbf3c41f7a815a48b301d0283')]\n(Background on this error at: https://sqlalche.me/e/20/gkpj)"}}
  {'type': 'missing', 'loc': ('response', 'updated_at'), 'msg': 'Field required', 'input': {'e': "(sqlite3.IntegrityError) UNIQUE constraint failed: tags.name\n[SQL: INSERT INTO tags (name, id) VALUES (?, ?), (?, ?) RETURNING name, id]\n[parameters: ('Гигиена', 'c42b94f4d0aa4910bc9241508540d8f8', 'Ванна', '1e773a3fbf3c41f7a815a48b301d0283')]\n(Background on this error at: https://sqlalche.me/e/20/gkpj)"}}

2024-09-07 18:07:15.507 | ERROR    | app.core.logger:log_exception:88 - Обработана ошибка: (sqlite3.IntegrityError) UNIQUE constraint failed: tags.name
[SQL: INSERT INTO tags (name, id) VALUES (?, ?), (?, ?) RETURNING name, id]
[parameters: ('Гигиена', '17fa22997d8641439436dfe06b95a043', 'Ванна', '2c1fe0b158c34bc7b36761d16b5d56cf')]
(Background on this error at: https://sqlalche.me/e/20/gkpj)
2024-09-07 18:08:26.128 | ERROR    | app.core.logger:log_exception:88 - Обработана ошибка: (sqlite3.IntegrityError) UNIQUE constraint failed: tags.name
[SQL: INSERT INTO tags (name, id) VALUES (?, ?), (?, ?) RETURNING name, id]
[parameters: ('Гигиена', '739cfeabc35649b4a3ac46e5da077220', 'Ванна', 'f6c6f282ee094408b58de4a21904f956')]
(Background on this error at: https://sqlalche.me/e/20/gkpj)
2024-09-07 18:09:13.417 | ERROR    | app.core.logger:log_exception:88 - Обработана ошибка: (sqlite3.IntegrityError) NOT NULL constraint failed: tags.name
[SQL: INSERT INTO tags (id) VALUES (?) RETURNING name, id]
[parameters: ('2dc0c46972c24c66bd7f2a7bd4423575',)]
(Background on this error at: https://sqlalche.me/e/20/gkpj)
2024-09-07 18:11:30.121 | ERROR    | app.core.logger:log_exception:88 - Обработана ошибка: greenlet_spawn has not been called; can't call await_only() here. Was IO attempted in an unexpected place? (Background on this error at: https://sqlalche.me/e/20/xd2s)
2024-09-07 18:11:44.485 | ERROR    | app.core.logger:log_exception:88 - Обработана ошибка: greenlet_spawn has not been called; can't call await_only() here. Was IO attempted in an unexpected place? (Background on this error at: https://sqlalche.me/e/20/xd2s)
2024-09-07 18:17:27.686 | ERROR    | app.core.logger:log_exception:88 - Обработана ошибка: Trgrfg
2024-09-07 18:18:30.607 | ERROR    | app.core.logger:log_exception:88 - Обработана ошибка: Trgrfg
2024-09-07 18:19:04.758 | ERROR    | app.core.logger:log_exception:88 - Обработана ошибка: greenlet_spawn has not been called; can't call await_only() here. Was IO attempted in an unexpected place? (Background on this error at: https://sqlalche.me/e/20/xd2s)
2024-09-07 18:20:28.319 | ERROR    | app.core.logger:log_exception:88 - Обработана ошибка: greenlet_spawn has not been called; can't call await_only() here. Was IO attempted in an unexpected place? (Background on this error at: https://sqlalche.me/e/20/xd2s)
2024-09-07 18:21:06.874 | ERROR    | app.core.logger:log_exception:88 - Обработана ошибка: greenlet_spawn has not been called; can't call await_only() here. Was IO attempted in an unexpected place? (Background on this error at: https://sqlalche.me/e/20/xd2s)
2024-09-07 18:22:45.856 | INFO     | app.main:log_requests:44 - POST http://127.0.0.1:8000/api/v1/notes/ - 401
2024-09-07 18:23:07.765 | INFO     | app.main:log_requests:44 - POST http://127.0.0.1:8000/api/v1/auth/refresh - 200
2024-09-07 18:23:29.719 | ERROR    | app.core.logger:log_exception:88 - Обработана ошибка: 'tags_names' is an invalid keyword argument for Note
2024-09-07 18:24:26.249 | ERROR    | app.core.logger:log_exception:88 - Обработана ошибка: greenlet_spawn has not been called; can't call await_only() here. Was IO attempted in an unexpected place? (Background on this error at: https://sqlalche.me/e/20/xd2s)
2024-09-07 18:25:36.783 | ERROR    | app.core.logger:log_exception:88 - Обработана ошибка: greenlet_spawn has not been called; can't call await_only() here. Was IO attempted in an unexpected place? (Background on this error at: https://sqlalche.me/e/20/xd2s)
2024-09-07 18:29:23.274 | ERROR    | app.core.logger:log_exception:88 - Обработана ошибка: 'CreateNoteSchema' object has no attribute 'id'
2024-09-07 18:31:05.374 | ERROR    | app.core.logger:log_exception:88 - Обработана ошибка: 'CreateNoteSchema' object has no attribute 'id'
2024-09-07 18:31:24.871 | ERROR    | app.core.logger:log_exception:88 - Обработана ошибка: greenlet_spawn has not been called; can't call await_only() here. Was IO attempted in an unexpected place? (Background on this error at: https://sqlalche.me/e/20/xd2s)
2024-09-07 18:32:02.395 | ERROR    | app.core.logger:log_exception:88 - Обработана ошибка: 'CreateNoteSchema' object has no attribute 'name'
2024-09-07 18:32:33.019 | ERROR    | app.core.logger:log_exception:88 - Обработана ошибка: greenlet_spawn has not been called; can't call await_only() here. Was IO attempted in an unexpected place? (Background on this error at: https://sqlalche.me/e/20/xd2s)
2024-09-07 18:37:58.157 | ERROR    | app.core.logger:log_exception:88 - Обработана ошибка: CRUDServiceMixin.list() missing 1 required keyword-only argument: 'limit'
2024-09-07 18:39:03.990 | ERROR    | app.core.logger:log_exception:88 - Обработана ошибка: Entity namespace for "tags" has no property "note_id"
2024-09-07 18:44:23.515 | INFO     | app.main:log_requests:44 - POST http://127.0.0.1:8000/api/v1/notes/ - 401
2024-09-07 18:44:36.905 | INFO     | app.main:log_requests:44 - POST http://127.0.0.1:8000/api/v1/auth/login - 200
2024-09-07 18:44:53.887 | INFO     | app.main:log_requests:44 - POST http://127.0.0.1:8000/api/v1/notes/ - 401
2024-09-07 18:45:02.918 | INFO     | app.main:log_requests:44 - POST http://127.0.0.1:8000/api/v1/auth/login - 200
2024-09-07 18:45:17.346 | ERROR    | app.core.logger:log_exception:88 - Обработана ошибка: 'Note' object has no attribute 'name'
2024-09-07 18:45:40.264 | INFO     | app.main:log_requests:44 - POST http://127.0.0.1:8000/api/v1/notes/ - 201
2024-09-07 18:54:15.233 | INFO     | app.main:log_requests:44 - POST http://127.0.0.1:8000/api/v1/auth/login - 200
2024-09-07 18:54:57.172 | ERROR    | app.core.logger:log_exception:88 - Обработана ошибка: name 'result' is not defined
2024-09-07 18:55:37.926 | INFO     | app.main:log_requests:44 - POST http://127.0.0.1:8000/api/v1/notes/ - 201
2024-09-07 18:56:02.660 | INFO     | app.main:log_requests:44 - POST http://127.0.0.1:8000/api/v1/notes/ - 201
2024-09-07 17:57:34.034 | INFO     | app.main:log_requests:44 - POST http://127.0.0.1:8000/api/v1/notes/ - 401
2024-09-07 17:57:40.978 | INFO     | app.main:log_requests:44 - POST http://127.0.0.1:8000/api/v1/auth/login - 200
2024-09-07 17:57:54.180 | INFO     | app.main:log_requests:44 - POST http://127.0.0.1:8000/api/v1/notes/ - 201
2024-09-07 17:58:28.247 | INFO     | app.main:log_requests:44 - POST http://127.0.0.1:8000/api/v1/notes/ - 201
2024-09-07 18:00:39.107 | INFO     | app.main:log_requests:44 - POST http://127.0.0.1:8000/api/v1/notes/ - 201
2024-09-07 18:05:01.649 | INFO     | app.main:log_requests:44 - POST http://127.0.0.1:8000/api/v1/notes/ - 201
2024-09-07 18:05:23.606 | INFO     | app.main:log_requests:44 - POST http://127.0.0.1:8000/api/v1/notes/ - 201
2024-09-07 18:05:37.761 | ERROR    | app.core.logger:log_exception:88 - Обработана ошибка: name 'user_id' is not defined
2024-09-07 18:07:01.799 | ERROR    | app.core.logger:log_exception:88 - Обработана ошибка: 'NoteService' object has no attribute 'repository_note'
2024-09-07 18:11:39.609 | ERROR    | app.core.logger:log_exception:88 - Обработана ошибка: RepositoryNote.get_user_notes() got multiple values for argument 'owner_id'
2024-09-07 18:13:12.791 | ERROR    | app.core.logger:log_exception:88 - Обработана ошибка: name 'note' is not defined
2024-09-07 18:14:52.139 | ERROR    | app.core.logger:log_exception:88 - Обработана ошибка: 'Note' object has no attribute 'name'
2024-09-07 18:16:10.483 | ERROR    | app.core.logger:log_exception:88 - Обработана ошибка: greenlet_spawn has not been called; can't call await_only() here. Was IO attempted in an unexpected place? (Background on this error at: https://sqlalche.me/e/20/xd2s)
2024-09-07 18:19:16.319 | INFO     | app.main:log_requests:44 - GET http://127.0.0.1:8000/api/v1/notes/?limit=10&skip=0 - 401
2024-09-07 18:19:25.466 | INFO     | app.main:log_requests:44 - POST http://127.0.0.1:8000/api/v1/auth/login - 200
2024-09-07 18:19:39.391 | ERROR    | app.core.logger:log_exception:88 - Обработана ошибка: Entity namespace for "Mapper[Tag(tags)]" has no property "owner_id"
2024-09-07 18:20:23.887 | INFO     | app.main:log_requests:44 - GET http://127.0.0.1:8000/docs - 200
2024-09-07 18:20:25.741 | INFO     | app.main:log_requests:44 - GET http://127.0.0.1:8000/openapi.json - 200
2024-09-07 18:20:35.894 | INFO     | app.main:log_requests:44 - POST http://127.0.0.1:8000/api/v1/auth/login - 200
2024-09-07 18:20:48.891 | ERROR    | app.core.logger:log_exception:88 - Обработана ошибка: greenlet_spawn has not been called; can't call await_only() here. Was IO attempted in an unexpected place? (Background on this error at: https://sqlalche.me/e/20/xd2s)
2024-09-07 18:22:23.053 | ERROR    | app.core.logger:log_exception:88 - Обработана ошибка: greenlet_spawn has not been called; can't call await_only() here. Was IO attempted in an unexpected place? (Background on this error at: https://sqlalche.me/e/20/xd2s)
2024-09-07 18:25:11.964 | ERROR    | app.core.logger:log_exception:88 - Обработана ошибка: name 'selectinload' is not defined
2024-09-07 18:26:21.608 | INFO     | app.main:log_requests:44 - GET http://127.0.0.1:8000/api/v1/notes/?limit=10&skip=0 - 200
2024-09-07 18:26:35.264 | INFO     | app.main:log_requests:44 - GET http://127.0.0.1:8000/api/v1/notes/?limit=100&skip=10 - 200
2024-09-07 18:26:49.758 | INFO     | app.main:log_requests:44 - GET http://127.0.0.1:8000/api/v1/notes/?limit=100 - 200
2024-09-07 18:27:03.819 | ERROR    | app.core.logger:log_exception:88 - Обработана ошибка: CRUDServiceMixin.delete() got an unexpected keyword argument 'id'
2024-09-07 18:27:42.890 | ERROR    | app.core.logger:log_exception:88 - Обработана ошибка: Entity namespace for "notes" has no property "obj_id"
2024-09-07 18:29:28.532 | INFO     | app.main:log_requests:44 - DELETE http://127.0.0.1:8000/api/v1/notes/44cff9b1-b5ae-4220-bb9e-a53d700aee7f - 200
2024-09-07 18:29:36.975 | INFO     | app.main:log_requests:44 - GET http://127.0.0.1:8000/api/v1/notes/?limit=100 - 200
2024-09-07 18:30:20.847 | INFO     | app.main:log_requests:44 - POST http://127.0.0.1:8000/api/v1/notes/?limit_tags=20 - 201
2024-09-07 18:30:35.266 | INFO     | app.main:log_requests:44 - GET http://127.0.0.1:8000/api/v1/notes/?limit=100&skip=20 - 200
2024-09-07 18:40:39.600 | INFO     | app.main:log_requests:44 - GET http://127.0.0.1:8000/docs - 200
2024-09-07 18:40:40.792 | INFO     | app.main:log_requests:44 - GET http://127.0.0.1:8000/openapi.json - 200
2024-09-07 18:40:55.174 | ERROR    | app.core.logger:log_exception:88 - Обработана ошибка: type object 'User' has no attribute 'email'
2024-09-07 18:42:07.081 | INFO     | app.main:log_requests:44 - GET http://127.0.0.1:8000/docs - 200
2024-09-07 18:42:10.001 | INFO     | app.main:log_requests:44 - GET http://127.0.0.1:8000/openapi.json - 200
2024-09-07 18:42:16.302 | ERROR    | app.core.logger:log_exception:88 - Обработана ошибка: 'User' object has no attribute 'email'
2024-09-07 18:43:08.877 | INFO     | app.main:log_requests:44 - GET http://127.0.0.1:8000/docs - 200
2024-09-07 18:43:09.361 | INFO     | app.main:log_requests:44 - GET http://127.0.0.1:8000/openapi.json - 200
2024-09-07 18:43:14.715 | INFO     | app.main:log_requests:44 - POST http://127.0.0.1:8000/api/v1/users/ - 400
2024-09-07 18:43:21.853 | INFO     | app.main:log_requests:44 - POST http://127.0.0.1:8000/api/v1/users/ - 400
2024-09-07 18:43:36.714 | INFO     | app.main:log_requests:44 - POST http://127.0.0.1:8000/api/v1/users/ - 400
2024-09-07 18:45:28.152 | INFO     | app.main:log_requests:44 - POST http://127.0.0.1:8000/api/v1/users/ - 201
2024-09-07 18:45:43.569 | INFO     | app.main:log_requests:44 - POST http://127.0.0.1:8000/api/v1/auth/login - 422
2024-09-07 18:46:13.255 | ERROR    | app.core.logger:log_exception:88 - Обработана ошибка: 'User' object has no attribute 'email'
2024-09-07 18:46:49.825 | INFO     | app.main:log_requests:44 - POST http://127.0.0.1:8000/api/v1/auth/login - 200
2024-09-07 18:47:01.350 | INFO     | app.main:log_requests:44 - GET http://127.0.0.1:8000/api/v1/users/me - 200
